Workbook

Sheet Amarillo T12
A1: Income Statement - 12 Month
A3: Fund Type: All
A4: Period Range: Apr 2025 to Mar 2026 (Trailing 12 Months)
A5: Accounting Basis: Accrual
A6: GL Account Map: None - use master chart of accounts
A7: Level of Detail: Detail View
A8: Include Zero Balance GL Accounts: No
A10: Account Name | B10: Apr 2025 | C10: May 2025 | D10: Jun 2025 | E10: Jul 2025 | F10: Aug 2025 | G10: Sep 2025 | H10: Oct 2025 | I10: Nov 2025 | J10: Dec 2025 | K10: Jan 2026 | L10: Feb 2026 | M10: Mar 2026 | N10: Total | O10: Account Number
A11: Operating Income & Expense
A12: Income
A13: Rental Income
A14: Rent Income | B14: 78897.79 | C14: 79496 | D14: 77736 | E14: 83287.8 | F14: 84069 | G14: 79301 | H14: 72960.69 | I14: 72265 | J14: 70194.25 | K14: 69825 | L14: 69443.58 | M14: 76874.1 | N14: 914350.21 | O14: 4002
A15: Housing Choice Voucher- HUD or PCS | B15: 9599 | C15: 9847 | D15: 9838 | E15: 9024 | F15: 7454 | G15: 7454 | H15: 7757 | I15: 8124 | J15: 9236 | K15: 9918 | L15: 9860 | M15: 9962 | N15: 108073 | O15: 4003
A16: Concessions - Promotion | B16: -1978 | C16: -3000 | D16: -3043.5 | E16: -1269 | F16: -1646.5 | G16: -104.5 | H16: -1502.5 | I16: -1446 | J16: -1350 | K16: -3270 | L16: -6365 | M16: -12870 | N16: -37845 | O16: 4007
A17: Concessions - Resident Concession | B17: 0 | C17: -873.98 | D17: -75 | E17: 0 | F17: 0 | G17: -75 | H17: 0 | I17: -20.54 | J17: 0 | K17: -150.54 | L17: -885 | M17: 0 | N17: -2080.06 | O17: 4009
A18: Concessions - Student Discount | B18: 0 | C18: 0 | D18: 0 | E18: 0 | F18: 0 | G18: 0 | H18: -56 | I18: 0 | J18: 0 | K18: 0 | L18: 0 | M18: 0 | N18: -56 | O18: 4010
A19: Total Rental Income | B19: 86518.79 | C19: 85469.02 | D19: 84455.5 | E19: 91042.8 | F19: 89876.5 | G19: 86575.5 | H19: 79159.19 | I19: 78922.46 | J19: 78080.25 | K19: 76322.46 | L19: 72053.58 | M19: 73966.1 | N19: 982442.15
A20: Fee Income
A21: Month-to-Month Fee | B21: 350 | C21: 250 | D21: 250 | E21: 300 | F21: 250 | G21: 150 | H21: 150 | I21: 150 | J21: 200 | K21: 200 | L21: 350 | M21: 300 | N21: 2900 | O21: 4101
A22: Late Fee | B22: 497.5 | C22: -501 | D22: 303.38 | E22: -159.78 | F22: 483.6 | G22: -16.93 | H22: 127.13 | I22: -50.6 | J22: -56.09 | K22: -81.81 | L22: 70 | M22: -39 | N22: 576.4 | O22: 4102
A23: NSF Fee | B23: 40 | C23: -40 | D23: 0 | E23: 0 | F23: 0 | G23: 0 | H23: 0 | I23: 100 | J23: -100 | K23: 0 | L23: 0 | M23: 0 | N23: 0 | O23: 4104
A24: One Time Pet Fee | B24: 250 | C24: 525 | D24: 225 | E24: 1750 | F24: 550 | G24: 500 | H24: 450 | I24: 750 | J24: 150 | K24: 150 | L24: 450 | M24: 1300 | N24: 7050 | O24: 4105
A25: Monthly Pet Fee | B25: 400 | C25: 429 | D25: 425 | E25: 515 | F25: 534 | G25: 515.8 | H25: 605.67 | I25: 740 | J25: 650 | K25: 625 | L25: 550 | M25: 667 | N25: 6656.47 | O25: 4106
A26: RBP Income | B26: 118.11 | C26: 157.93 | D26: 49.34 | E26: 511.71 | F26: 60 | G26: 30 | H26: -30 | I26: 30 | J26: -40 | K26: 11 | L26: 0 | M26: 0 | N26: 898.09 | O26: 4121
A27: LLI Income | B27: 11.36 | C27: 82.29 | D27: 52.13 | E27: 172.99 | F27: 10 | G27: 10 | H27: -10 | I27: 10 | J27: 0 | K27: 0 | L27: 0 | M27: 0 | N27: 338.77 | O27: 4123
A28: Beagle TLW | B28: 0 | C28: 0 | D28: 11 | E28: -597.8 | F28: -58.95 | G28: -227.51 | H28: -181.25 | I28: 648.34 | J28: -368.21 | K28: 154.9 | L28: -589.88 | M28: 448.03 | N28: -761.33 | O28: 4124
A29: Total Fee Income | B29: 1666.97 | C29: 903.22 | D29: 1315.85 | E29: 2492.12 | F29: 1828.65 | G29: 961.36 | H29: 1111.55 | I29: 2377.74 | J29: 435.7 | K29: 1059.09 | L29: 830.12 | M29: 2676.03 | N29: 17658.4
A30: Pass Through
A31: Fixed Utility Income | B31: 0 | C31: 997.16 | D31: 423.66 | E31: 334.72 | F31: 567.5 | G31: 958.45 | H31: 897.33 | I31: 852.09 | J31: 1788.12 | K31: 1557.94 | L31: 1190.06 | M31: 1702.1 | N31: 11269.13 | O31: 4201
A32: Total Pass Through | B32: 0 | C32: 997.16 | D32: 423.66 | E32: 334.72 | F32: 567.5 | G32: 958.45 | H32: 897.33 | I32: 852.09 | J32: 1788.12 | K32: 1557.94 | L32: 1190.06 | M32: 1702.1 | N32: 11269.13
A33: Deposit & Maintenance Income
A34: Surrendered Security Deposit | B34: 0 | C34: 800 | D34: 800 | E34: 578 | F34: 351 | G34: 820 | H34: 560 | I34: 1060 | J34: 1000 | K34: 1900 | L34: 2325 | M34: 198 | N34: 10392 | O34: 4301
A35: Resident Responsible - Labor | B35: 0 | C35: 175 | D35: 0 | E35: 500 | F35: 0 | G35: 0 | H35: 0 | I35: 180 | J35: 0 | K35: 0 | L35: 0 | M35: 0 | N35: 855 | O35: 4303
A36: Resident Responsible - Supplies | B36: 0 | C36: 130 | D36: 45 | E36: 580 | F36: 415 | G36: 1540 | H36: 430 | I36: 4040 | J36: 0 | K36: 580 | L36: 640 | M36: 1840 | N36: 10240 | O36: 4304
A37: Resident Responsible - Cleaning | B37: 300 | C37: 1718.32 | D37: 1171 | E37: 1787 | F37: 1282 | G37: 2178.2 | H37: 1041.4 | I37: 837 | J37: 310 | K37: 4134 | L37: 5250 | M37: 1340 | N37: 21348.92 | O37: 4305
A38: Resident Responsible - Lockout/Lock Change | B38: 0 | C38: 0 | D38: 75 | E38: 230 | F38: 0 | G38: 0 | H38: 0 | I38: 80 | J38: 0 | K38: 0 | L38: 0 | M38: 0 | N38: 385 | O38: 4307
A39: Resident Responsible - Plumbing | B39: 0 | C39: 93.75 | D39: 0 | E39: 112.5 | F39: 0 | G39: 0 | H39: 0 | I39: 0 | J39: 0 | K39: 105.22 | L39: 0 | M39: 0 | N39: 311.47 | O39: 4309
A40: Resident Responsible - Haul Off | B40: 200 | C40: 1200 | D40: 1200 | E40: 1200 | F40: 1200 | G40: 2400 | H40: 400 | I40: 400 | J40: 200 | K40: 1200 | L40: 800 | M40: 800 | N40: 11200 | O40: 4310
A41: Resident Responsible - Miscellaneous | B41: 0 | C41: 130 | D41: 140 | E41: 711 | F41: 1500 | G41: 110 | H41: 800 | I41: 2602 | J41: 490 | K41: 90 | L41: 1575 | M41: 1830 | N41: 9978 | O41: 4311
A42: Total Deposit & Maintenance Income | B42: 500 | C42: 4247.07 | D42: 3431 | E42: 5698.5 | F42: 4748 | G42: 7048.2 | H42: 3231.4 | I42: 9199 | J42: 2000 | K42: 8009.22 | L42: 10590 | M42: 6008 | N42: 64710.39
...

Sheet Amarillo RR
A1: Rent Roll
A3: Units: Active
A4: Include Non-Revenue Units: No
A6: Unit | B6: BD/BA | C6: Tenant | D6: Status | E6: Sqft | F6: Market Rent | G6: Rent | H6: Deposit | I6: Lease From | J6: Lease To | K6: Move-in | L6: Move-out | M6: Monthly Rent / SF
A7: 101E | B7: 3/2.00 | C7: Alejandra M. Lopez | D7: Current | E7: 1184 | F7: 950 | G7: 1225 | H7: 0 | I7: 46066 | J7: 46418 | K7: 46066 | M7: 1.03
A8: 101W | B8: 2/1.00 | C8: Jackie L. Clark | D8: Current | E8: 784 | F8: 760 | G8: 952 | H8: 0 | I8: 45476 | J8: 46234 | K8: 45476 | M8: 1.21
A9: 102E | B9: 0/1.00 | C9: David M. Ardoff | D9: Current | E9: 400 | F9: 625 | G9: 650 | H9: 210 | I9: 45425 | J9: 46142 | K9: 45425 | M9: 1.63
A10: 102W | B10: 1/1.00 | C10: Ransom B. Wilson | D10: Current | E10: 592 | F10: 675 | G10: 952 | H10: 200 | I10: 45086 | J10: 46326 | K10: 45086 | M10: 1.61
A11: 103E | B11: 2/1.00 | C11: Tiarra L. Harris | D11: Current | E11: 784 | F11: 760 | G11: 1075 | H11: 200 | I11: 45288 | J11: 46265 | K11: 45288 | M11: 1.37
A12: 103W | B12: 3/2.00 | C12: Selena Montes | D12: Current | E12: 1184 | F12: 950 | G12: 1225 | H12: 350 | I12: 45890 | J12: 46234 | K12: 45890 | M12: 1.03
A13: 104E | B13: 1/1.00 | C13: Bobby R. Lamb | D13: Current | E13: 592 | F13: 675 | G13: 675 | H13: 0 | I13: 46071 | J13: 46418 | K13: 46071 | M13: 1.14
A14: 104W | B14: 1/1.00 | C14: Ruby Renteria | D14: Evict | E14: 592 | F14: 675 | G14: 675 | H14: 0 | I14: 45995 | J14: 46356 | K14: 45995 | M14: 1.14
A15: 105E | B15: 1/1.00 | C15: Adam C. Chinea | D15: Current | E15: 592 | F15: 675 | G15: 952 | H15: 200 | I15: 45328 | J15: 46418 | K15: 45328 | M15: 1.61
A16: 105W | B16: 1/1.00 | C16: Mary C. Purviance | D16: Current | E16: 592 | F16: 675 | G16: 845 | H16: 200 | I16: 45303 | J16: 46387 | K16: 45303 | M16: 1.43
A17: 106E | B17: 1/1.00 | C17: Torrey Welch | D17: Notice-Unrented | E17: 592 | F17: 675 | G17: 952 | H17: 200 | I17: 45761 | J17: 46112 | K17: 45761 | L17: 46121 | M17: 1.61
A18: 106W | B18: 1/1.00 | C18: Charles L. Lutz | D18: Current | E18: 592 | F18: 675 | G18: 952 | H18: 850 | I18: 45008 | J18: 46446 | K18: 45008 | M18: 1.61
A19: 107E | B19: 3/2.00 | C19: Natalia Garza | D19: Current | E19: 1184 | F19: 950 | G19: 1147 | H19: 210 | I19: 45474 | K19: 45474 | M19: 0.97
A20: 107W | B20: 1/1.00 | C20: Quinston C. Graves | D20: Current | E20: 592 | F20: 675 | G20: 675 | H20: 0 | I20: 46087 | J20: 46446 | K20: 46087 | M20: 1.14
A21: 108E | B21: 2/1.00 | C21: Jiorge Ayala | D21: Current | E21: 784 | F21: 760 | G21: 825 | H21: 0 | I21: 46082 | J21: 46446 | K21: 46082 | M21: 1.05
A22: 108W | B22: 1/1.00 | C22: Chris K. Even | D22: Current | E22: 592 | F22: 675 | G22: 845 | H22: 350 | I22: 45839 | J22: 46203 | K22: 45839 | M22: 1.43
A23: 109E | B23: 0/1.00 | C23: Meagon R. Laws | D23: Evict | E23: 400 | F23: 625 | G23: 750 | H23: 350 | I23: 45791 | J23: 46326 | K23: 45791 | M23: 1.88
A24: 109W | B24: 1/1.00 | C24: Nichole A. Servantez | D24: Current | E24: 592 | F24: 675 | G24: 845 | H24: 350 | I24: 45918 | J24: 46265 | K24: 45918 | M24: 1.43
A25: 110E | B25: 1/1.00 | D25: Vacant-Unrented | E25: 592 | F25: 675 | H25: 0
A26: 110W | B26: 1/1.00 | C26: Christopher C. Hood | D26: Current | E26: 592 | F26: 675 | G26: 675 | H26: 0 | I26: 46000 | J26: 46356 | K26: 46000 | M26: 1.14
A27: 111E | B27: 1/1.00 | C27: Kaylee H. Bunt | D27: Current | E27: 592 | F27: 675 | G27: 825 | H27: 0 | I27: 46023 | J27: 46387 | K27: 46023 | M27: 1.39
A28: 111W | B28: 1/1.00 | C28: Terry Morford | D28: Current | E28: 592 | F28: 675 | G28: 675 | H28: 0 | I28: 44652 | J28: 46418 | K28: 44805 | M28: 1.14
A29: 112E | B29: 1/1.00 | C29: Tara Pantel | D29: Current | E29: 592 | F29: 675 | G29: 795 | H29: 0 | I29: 44652 | K29: 44805 | M29: 1.34
A30: 112W | B30: 1/1.00 | C30: Robert C. Lyons | D30: Current | E30: 592 | F30: 675 | G30: 952 | H30: 350 | I30: 45790 | J30: 46507 | K30: 45790 | M30: 1.61
A31: 113E | B31: 1/1.00 | C31: Paul Maurice | D31: Current | E31: 592 | F31: 650 | G31: 952 | H31: 200 | I31: 45267 | J31: 46387 | K31: 45267 | M31: 1.61
A32: 113W | B32: 1/1.00 | C32: Travis L. Hart | D32: Notice-Unrented | E32: 592 | F32: 675 | G32: 845 | H32: 350 | I32: 45863 | J32: 46234 | K32: 45863 | L32: 46121 | M32: 1.43
A33: 114E | B33: 0/1.00 | C33: Jorden N. Zimmermann | D33: Notice-Unrented | E33: 400 | F33: 625 | G33: 625 | H33: 0 | I33: 46078 | J33: 46418 | K33: 46078 | L33: 46125 | M33: 1.56
A34: 114W | B34: 1/1.00 | C34: Pablo S. Davila | D34: Current | E34: 592 | F34: 675 | G34: 825 | H34: 825 | I34: 46082 | J34: 46265 | K34: 46082 | M34: 1.39
A35: 115E | B35: 2/1.00 | C35: Suzette A. Marsh | D35: Current | E35: 784 | F35: 760 | G35: 1158 | H35: 200 | I35: 45575 | J35: 46295 | K35: 45575 | M35: 1.48
A36: 115W | B36: 1/1.00 | C36: Amanda R. Montez | D36: Current | E36: 592 | F36: 675 | G36: 650 | H36: 625 | I36: 45078 | J36: 46538 | K36: 45078 | M36: 1.1
A37: 116E | B37: 3/2.00 | C37: Shuquetia R. Dexter | D37: Current | E37: 1184 | F37: 950 | G37: 1075 | H37: 210 | I37: 45484 | J37: 46203 | K37: 45484 | M37: 0.91
A38: 116W | B38: 1/1.00 | C38: Joseph D. Moore | D38: Notice-Rented | E38: 592 | F38: 675 | G38: 952 | H38: 0 | I38: 45078 | J38: 46295 | K38: 45078 | L38: 46112 | M38: 1.61
A39: 117E | B39: 1/1.00 | C39: Rolando G. Rodriguez | D39: Current | E39: 592 | F39: 675 | G39: 695 | H39: 0 | I39: 45964 | J39: 46326 | K39: 45964 | M39: 1.17
A40: 117W | B40: 1/1.00 | C40: Kerry L. Dittrich | D40: Current | E40: 592 | F40: 675 | G40: 993 | H40: 0 | I40: 46057 | J40: 46418 | K40: 46057 | M40: 1.68
A41: 118E | B41: 1/1.00 | C41: Cassandra K. Gonzales | D41: Current | E41: 592 | F41: 675 | G41: 825 | H41: 0 | I41: 46071 | J41: 46418 | K41: 46071 | M41: 1.39
A42: 118W | B42: 1/1.00 | C42: Christopher Mitchell | D42: Current | E42: 592 | F42: 675 | G42: 879 | H42: 0 | I42: 45055 | J42: 46173 | K42: 45055 | M42: 1.48
...

Sheet Oak T-12
A1: Oak Cliff Multifamily
A2: Profit and Loss by Month
A3: Rolling 12 Month
B5: Jun-25 | C5: Jul-25 | D5: Aug-25 | E5: Sep-25 | F5: Oct-25 | G5: Nov-25 | H5: Dec-25 | I5: Jan-26 | J5: Feb-26 | K5: Mar-26 | L5: Apr-26 | M5: May-26 | N5: Total
A6: Income
A7: RENTAL INCOME | B7: 122840.49 | C7: 123040.73 | D7: 121596.41 | E7: 121318.15 | F7: 123154.81 | G7: 130433.66 | H7: 128103.55 | I7: 133464.29 | J7: 139847.48 | K7: 141809.5 | L7: 136166.73 | M7: 140383.68 | N7: 1562159.5
A8: TOTAL RENTS | B8: 122840.49 | C8: 123040.73 | D8: 121596.41 | E8: 121318.15 | F8: 123154.81 | G8: 130433.66 | H8: 128103.55 | I8: 133464.29 | J8: 139847.48 | K8: 141809.5 | L8: 136166.73 | M8: 140383.68 | N8: 1562159.5
A9: CONCESSIONS | B9: -200 | C9: -400 | D9: -425 | E9: -850 | F9: -510 | G9: -2965 | H9: -1105 | I9: -840 | J9: -1401 | K9: -1309 | L9: -850 | M9: -1399.68 | N9: -12254.68
A10: FEES
A11: NSF Fees Collected | B11: 0 | C11: 0 | D11: 0 | E11: 0 | F11: 0 | G11: 0 | H11: 0 | I11: 0 | J11: 35 | K11: 35 | L11: 0 | M11: 140 | N11: 210
A12: Transfer Fee | B12: 0 | C12: 0 | D12: 0 | E12: 200 | F12: 0 | G12: 0 | H12: 0 | I12: 0 | J12: 0 | K12: 0 | L12: 0 | M12: 0 | N12: 200
A13: Pet Fee | B13: 0 | C13: 0 | D13: 200 | E13: 100 | F13: 0 | G13: 100 | H13: 50 | I13: 300 | J13: 300 | K13: 0 | L13: 0 | M13: 0 | N13: 1050
A14: Admin Fee | B14: 0 | C14: 0 | D14: 268 | E14: 0 | F14: 0 | G14: 0 | H14: 0 | I14: 0 | J14: 0 | K14: 0 | L14: 0 | M14: 0 | N14: 268
A15: Application Fee | B15: 0 | C15: 0 | D15: 0 | E15: 0 | F15: 0 | G15: 0 | H15: 0 | I15: 0 | J15: 0 | K15: 0 | L15: 0 | M15: 0 | N15: 0
A16: Risk Fee | B16: 0 | C16: 0 | D16: 0 | E16: 0 | F16: 0 | G16: 0 | H16: 0 | I16: 0 | J16: 0 | K16: 0 | L16: 0 | M16: 0 | N16: 0
A17: Late Fee | B17: 1350.84 | C17: 563 | D17: 772.5 | E17: 742 | F17: 220 | G17: 1244 | H17: 881.7 | I17: 279.5 | J17: 546 | K17: 388.2 | L17: 0 | M17: 725.17 | N17: 7712.91
A18: Utility Reimbursement Fee | B18: 140 | C18: 101 | D18: 59 | E18: 90 | F18: 50 | G18: 110 | H18: 65 | I18: 65 | J18: 70 | K18: 80 | L18: 50 | M18: 80 | N18: 960
A19: TOTAL FEES | B19: 1490.84 | C19: 664 | D19: 1299.5 | E19: 1132 | F19: 270 | G19: 1454 | H19: 996.7 | I19: 644.5 | J19: 951 | K19: 503.2 | L19: 50 | M19: 945.17 | N19: 10400.91
A20: PARKING INCOME | B20: 707 | C20: 625 | D20: 645 | E20: 505 | F20: 410 | G20: 525 | H20: 375 | I20: 485 | J20: 505 | K20: 405 | L20: 480 | M20: 455 | N20: 6122
A21: TENANT IMPROVEMENTS | B21: 25 | C21: 0 | D21: 60 | E21: 60 | F21: 0 | G21: 40 | H21: 0 | I21: 100 | J21: 0 | K21: 0 | L21: 0 | M21: 0 | N21: 285
A22: MISCELLANEOUS INCOME | B22: 0 | C22: 0 | D22: 0 | E22: 0 | F22: 0 | G22: 0 | H22: 0 | I22: 25 | J22: 10 | K22: 0 | L22: 0 | M22: 0 | N22: 35
A23: Total Operating Income | B23: 124863.33 | C23: 123929.73 | D23: 123175.91 | E23: 122165.15 | F23: 123324.81 | G23: 129487.66 | H23: 128370.25 | I23: 133878.79 | J23: 139912.48 | K23: 141408.7 | L23: 135846.73 | M23: 140384.17 | N23: 1566747.7
A26: Expenses
A27: 1. OPERATING EXPENSES (CONTROLLABLE)
A28: CONTROLLABLE EXPENSES
A29: CONTRACT SERVICES - ALL OTHER / REPAIRS & MAINTENANCE | C29: 85 | D29: 1255 | F29: 1885 | G29: 1500 | K29: 3200 | L29: 350 | M29: 6664 | N29: 14939
A30: COURT / EVICTION FEES | B30: 1000 | C30: 1541.82 | F30: 1231 | G30: 695.5 | H30: 1740.41 | I30: 1349 | J30: 948 | K30: 828 | L30: 1623 | M30: 1632.01 | N30: 12588.74
A31: LANDSCAPING | B31: 250 | C31: 250 | D31: 250 | E31: 250 | F31: 250 | G31: 250 | H31: 250 | I31: 250 | J31: 250 | K31: 250 | L31: 250 | M31: 250 | N31: 3000
A32: PAYROLL MAINTENANCE TEAM | B32: 10011 | C32: 9581.5 | D32: 9525.25 | E32: 10592.63 | F32: 11379.51 | G32: 12385.5 | H32: 10418.7 | I32: 11598 | J32: 14400 | K32: 14794.92 | L32: 11108 | M32: 14624.82 | N32: 140419.83
A33: PAYROLL OFFICE TEAM | B33: 8312 | C33: 10516 | D33: 14379.73 | E33: 10870.98 | F33: 12896 | G33: 10030 | H33: 15149.31 | I33: 6786.4 | J33: 9080 | K33: 13578.5 | L33: 11430.5 | M33: 13323 | N33: 136352.42
A34: PEST CONTROL | B34: 252 | C34: 252 | D34: 266 | E34: 266 | F34: 266 | G34: 266 | H34: 266 | I34: 266 | J34: 266 | K34: 266 | L34: 222.54 | M34: 81.19 | N34: 2935.73
A35: SOFTWARE / SUBSCRIPTIONS | B35: 205 | C35: 745.29 | D35: 800 | E35: 324.24 | F35: 1347.12 | G35: 1108.06 | H35: 428.12 | I35: 428.12 | J35: 868.12 | K35: 28.12 | L35: 428.12 | M35: 428.12 | N35: 7138.43
A36: LICENSE / PERMITS | F36: 1768 | M36: 609 | N36: 2377
A37: SECURITY | E37: 420 | F37: 780 | G37: 1120 | H37: 880 | I37: 320 | J37: 680 | K37: 720 | L37: 375 | M37: 480 | N37: 5775
A38: SUPPLIES | B38: 3090.92 | C38: 3306 | D38: 4404.3 | E38: 2868 | F38: 2938.66 | G38: 3667.32 | H38: 4005.48 | I38: 3880.87 | J38: 3341 | K38: 2126.55 | L38: 2974.63 | M38: 1563.61 | N38: 38167.34
A39: TELEPHONE / INTERNET | B39: 185.78 | C39: 195.84 | D39: 195.84 | E39: 195.84 | F39: 195.84 | G39: 195.84 | H39: 195.84 | I39: 195.84 | J39: 195.84 | K39: 140.74 | L39: 222.54 | M39: 222.49 | N39: 2338.27
A40: UTILITY - ELECTRIC | B40: 527.87 | C40: 561.65 | D40: 567.47 | E40: 617.3 | F40: 630.54 | G40: 604.17 | H40: 533.98 | I40: 616.74 | J40: 569.6 | K40: 555.17 | L40: 499.5 | M40: 527.35 | N40: 6811.34
A41: UTILITY - GAS | B41: 110.26 | C41: 117.38 | D41: 118.18 | E41: 117.06 | F41: 115.91 | G41: 117.36 | H41: 128.56 | I41: 127.18 | J41: 123.34 | K41: 121.26 | L41: 127.82 | M41: 125.52 | N41: 1449.83
A42: UTILITY - TRASH | B42: 3618.74 | C42: 3796.42 | D42: 3839.15 | E42: 3671.33 | F42: 3667.32 | G42: 4434.35 | H42: 4087 | I42: 3821.57 | J42: 2478.05 | K42: 3793.62 | L42: 4974.67 | M42: 4974.67 | N42: 47156.89
A43: UTILITY - WATER | B43: 8686.1 | C43: 9248.03 | D43: 8487.01 | E43: 10964.96 | F43: 8066.87 | G43: 8070.54 | H43: 8288.13 | I43: 10766.26 | J43: 8988.06 | K43: 7897.11 | L43: 6566.42 | M43: 6580.74 | N43: 102610.23
...

Sheet Oak RR
A1: Oak Cliff Multifamily As of: 06/17/2026 (Today) Include Non-Revenue Units: No Include Advertised Rent: Yes
A2: Unit | B2: BD/ BA | C2: Unit Type | D2: Tenant | E2: Status | F2: Sqft | G2: Market Rent | H2: Rent | I2: Monthly Charges | J2: Deposit | K2: Lease From | L2: Lease To | M2: Move-in | N2: Move-out
A3: Unit2/1.00 101 | C3: 2/1 | E3: Vacant-Rented | F3: 762 | G3: 1200 | I3: 0 | J3: 0
A4: Unit1/1.00 102 | C4: 1/1 | D4: James Burks | E4: Current | F4: 651 | G4: 1100 | H4: 1100 | J4: 0 | K4: 45003 | L4: 46446 | M4: 45312
A5: Unit1/1.00 103 | C5: 1/1 | D5: Don Boyd (DHA - VOUCHER) | E5: Current | F5: 651 | G5: 1100 | H5: 1050 | J5: 300 | K5: 44927 | L5: 46428 | M5: 44945
A6: Unit1/1.00 104 | C6: 1/1 | D6: Audrey (GPH-Voucher) Jones | E6: Current | F6: 651 | G6: 1100 | H6: 1050 | J6: 500 | K6: 45499 | L6: 46568 | M6: 45499
A7: Unit1/1.00 105 | C7: 1/1 | D7: Tradavius Walker | E7: Current | F7: 651 | G7: 1100 | H7: 1050 | J7: 500 | K7: 46042 | L7: 46387 | M7: 46042
A8: Unit1/1.00 106 | C8: 1/1 | D8: Victoria Burley | E8: Current | F8: 651 | G8: 1100 | H8: 1010 | J8: 500 | K8: 45936 | L8: 46300 | M8: 45936
A9: Unit1/1.00 107 | C9: 1/1 | D9: Gloria Nzeadibe | E9: Current | F9: 651 | G9: 1100 | H9: 1050 | J9: 500 | K9: 46054 | L9: 46418 | M9: 46054
A10: Unit2/1.00 108 | C10: 2/1 | D10: Crystal Brazile | E10: Current | F10: 762 | G10: 1200 | H10: 1200 | J10: 500 | K10: 46178 | L10: 46568 | M10: 46178
A11: Unit2/1.00 109 | C11: 2/1 | D11: Anita Rincon | E11: Current | F11: 762 | G11: 1200 | H11: 1150 | J11: 300 | K11: 45084 | L11: 46538 | M11: 45085
A12: Unit1/1.00 110 | C12: 1/1 | D12: Floyd Johnson | E12: Current | F12: 651 | G12: 1100 | H12: 1050 | J12: 400 | K12: 46054 | L12: 46418 | M12: 46054
A13: Unit1/1.00 111 | C13: 1/1 | D13: Pearlie Smith | E13: Current | F13: 651 | G13: 1100 | H13: 1010 | J13: 500 | K13: 45841 | L13: 46599 | M13: 45841
A14: Unit1/1.00 112 | C14: 1/1 | D14: Christopher Tarver (DHA - VOUCHER) | E14: Current | F14: 651 | G14: 1100 | H14: 1050 | J14: 250 | K14: 45352 | L14: 46479 | M14: 44615
A15: Unit1/1.00 113 | C15: 1/1 | D15: Chesley Griffin (DHA - RAPID - NO VOUCHER) | E15: Current | F15: 651 | G15: 1100 | H15: 1075 | J15: 500 | K15: 45514 | L15: 46234 | M15: 45154
A16: Unit1/1.00 114 | C16: 1/1 | D16: Andre Johnson | E16: Current | F16: 651 | G16: 1100 | H16: 1030 | I16: 15 | J16: 0 | K16: 45108 | L16: 46568 | M16: 44348
A17: Unit1/1.00 115 | C17: 1/1 | D17: Mary/Billy Prater/ Skinner | E17: Current | F17: 651 | G17: 1100 | H17: 975 | I17: 15 | J17: 0 | K17: 45905 | L17: 46446 | M17: 45905
A18: Unit2/1.00 116 | C18: 2/1 | D18: Jimmy Pipkins | E18: Current | F18: 762 | G18: 1200 | H18: 1150 | J18: 0 | K18: 45383 | L18: 46477 | M18: 44169
A19: Unit2/1.00 201 | C19: 2/1 | D19: Lashonna Weaver | E19: Current | F19: 762 | G19: 1200 | H19: 1100 | J19: 0 | K19: 45818 | L19: 46507 | M19: 45818
A20: Unit2/1.00 202 | C20: 2/1 | D20: Vermon Mixon | E20: Current | F20: 762 | G20: 1200 | H20: 1035 | J20: 500 | K20: 45550 | L20: 46295 | M20: 45550
A21: Unit2/1.00 203 | C21: 2/1 | D21: Carol Williams | E21: Current | F21: 762 | G21: 1200 | H21: 1100 | J21: 0 | K21: 45912 | L21: 46276 | M21: 45912
A22: Unit2/1.00 204 | C22: 2/1 | D22: Kenya Bryant | E22: Current | F22: 762 | G22: 1200 | H22: 1100 | J22: 0 | K22: 46129 | L22: 46203 | M22: 46129
A23: Unit2/1.00 205 | C23: 2/1 | D23: Robert Brown | E23: Current | F23: 762 | G23: 1200 | H23: 1100 | J23: 500 | K23: 46116 | L23: 46480 | M23: 46116
A24: Unit2/1.00 206 | C24: 2/1 | D24: Rebecca Tinnell | E24: Current | F24: 762 | G24: 1200 | H24: 1100 | J24: 300 | K24: 45992 | L24: 46356 | M24: 45992
A25: Unit2/1.00 207 | C25: 2/1 | D25: Rayshundre Jackson | E25: Notice-Unrented | F25: 762 | G25: 1200 | H25: 1100 | J25: 500 | K25: 46054 | L25: 46418 | M25: 46054 | N25: 46190
A26: Unit1/1.00 208 | C26: 1/1 | D26: Jamie Aubrey (DHA - RAPID - NO VOUCHER) | E26: Current | F26: 651 | G26: 1100 | H26: 925 | J26: 500 | K26: 45222 | L26: 46568 | M26: 45231
A27: Unit2/1.00 209 | C27: 2/1 | D27: Quellar Malone | E27: Current | F27: 762 | G27: 1200 | H27: 1150 | I27: 25 | J27: 500 | K27: 45530 | L27: 46259 | M27: 45530
A28: Unit2/1.00 210 | C28: 2/1 | D28: Billy Hall | E28: Current | F28: 762 | G28: 1200 | H28: 1150 | J28: 500 | K28: 45352 | L28: 46568 | M28: 45352
A29: Unit2/1.00 211 | C29: 2/1 | D29: Schreta Goynes | E29: Current | F29: 762 | G29: 1200 | H29: 1100 | J29: 300 | K29: 45962 | L29: 46326 | M29: 45962
A30: Unit2/1.00 212 | C30: 2/1 | D30: Robert Moffett | E30: Current | F30: 762 | G30: 1200 | H30: 1075 | J30: 0 | K30: 45819 | L30: 46568 | M30: 45819
A31: Unit2/1.00 213 | C31: 2/1 | D31: Evangelina Cueto | E31: Current | F31: 762 | G31: 1200 | H31: 1125 | J31: 500 | K31: 45332 | L31: 46446 | M31: 45332
A32: Unit2/1.00 214 | C32: 2/1 | D32: Jacobyia Johnson | E32: Current | F32: 762 | G32: 1200 | H32: 1100 | J32: 300 | K32: 45999 | L32: 46356 | M32: 45999
A33: Unit2/1.00 215 | C33: 2/1 | D33: Metro Care | E33: Current | F33: 762 | G33: 1200 | H33: 1075 | J33: 0 | K33: 45909 | L33: 46273 | M33: 45909
A34: Unit2/1.00 216 | C34: 2/1 | D34: Sadie Bernard | E34: Current | F34: 762 | G34: 1200 | H34: 1150 | I34: 25 | J34: 500 | K34: 45544 | L34: 46273 | M34: 45544
A35: Unit2/1.00 217 | C35: 2/1 | D35: Arnoldo Rafael Torrealba Mujica | E35: Current | F35: 762 | G35: 1200 | H35: 1100 | J35: 0 | K35: 45282 | L35: 46356 | M35: 45334
A36: Unit2/1.00 218 | C36: 2/1 | D36: Jessie Johnson | E36: Current | F36: 762 | G36: 1200 | H36: 1100 | I36: 10 | J36: 500 | K36: 46120 | L36: 46484 | M36: 46120
A37: Unit1/1.00 219 | C37: 1/1 | D37: Helene Johnson | E37: Current | F37: 651 | G37: 1100 | H37: 1050 | J37: 300 | K37: 45992 | L37: 46356 | M37: 45992
A38: Unit2/1.00 220 | C38: 2/1 | E38: Vacant-Unrented | F38: 762 | G38: 1200 | I38: 0 | J38: 0
A39: Unit2/1.00 221 | C39: 2/1 | D39: Hugo Sanchez | E39: Current | F39: 762 | G39: 1200 | H39: 1150 | I39: 100 | J39: 0 | K39: 45653 | L39: 46507 | M39: 45653
A40: Unit2/1.00 222 | C40: 2/1 | D40: Willie Jackson | E40: Current | F40: 762 | G40: 1200 | H40: 1100 | J40: 0 | K40: 46096 | L40: 46446 | M40: 46096
...

Sheet WTAMSH T-12
A1: Income Statement
A2: April 2025 - Mar 2026
B4: Account | C4: Apr 2025 | D4: May 2025 | E4: Jun 2025 | F4: Jul 2025 | G4: Aug 2025 | H4: Sep 2025 | I4: Oct 2025 | J4: Nov 2025 | K4: Dec 2025 | L4: Jan 2026 | M4: Feb 2026 | N4: Mar 2026 | O4: Total
B6: Gross Potential Rent
B7: Market Rent | C7: 126104.35 | D7: 140785.18 | E7: 107855.71 | F7: 99225.4 | G7: 96782.6 | H7: 117223.97 | I7: 109514.26 | J7: 109580.51 | K7: 108553.11 | L7: 99242.36 | M7: 105029.49 | N7: 109528.05 | O7: =SUM(C7:N7) -> 1329425
B8: Gross Potential Rent | C8: 126104.35 | D8: 140785.18 | E8: 107855.71 | F8: 99225.4 | G8: 96782.6 | H8: 117223.97 | I8: 109514.26 | J8: 109580.51 | K8: 108553.11 | L8: 99242.36 | M8: 105029.49 | N8: 109528.05 | O8: =SUM(C8:N8) -> 1329425
B10: Utility set up fee-Recovery | C10: 150 | D10: 1500 | E10: 525 | F10: 600 | G10: 8475 | H10: 675 | I10: 300 | J10: 225 | K10: 150 | L10: 900 | M10: 300 | N10: 430.65 | O10: =SUM(C10:N10) -> 14230.65
B12: Residential Rental Adjustments
B13: Application Fees | C13: 0 | D13: 0 | E13: 0 | F13: 0 | G13: 0 | H13: 0 | I13: 0 | J13: 0 | K13: -200 | L13: 0 | M13: 0 | N13: 0 | O13: =SUM(C13:N13) -> -200
B14: Residential Rental Adjustments | C14: 0 | D14: 0 | E14: 0 | F14: 0 | G14: 0 | H14: 0 | I14: 0 | J14: 0 | K14: -200 | L14: 0 | M14: 0 | N14: 0 | O14: =SUM(C14:N14) -> -200
B16: Residential Other Revenues
B17: Admin Fee | C17: 154 | D17: 0 | E17: 0 | F17: 0 | G17: 0 | H17: 0 | I17: 0 | J17: 0 | K17: 0 | L17: 0 | M17: 0 | N17: 0 | O17: =SUM(C17:N17) -> 154
B18: Late Charges | C18: 1847.82 | D18: 1830.54 | E18: 1503.26 | F18: 1403.56 | G18: 710.78 | H18: 1153.7 | I18: 1046.31 | J18: 1170.97 | K18: 1543.04 | L18: 1388.53 | M18: 1922.81 | N18: 1173.08 | O18: =SUM(C18:N18) -> 16694.4
B19: Miscellaneous Income | C19: 0 | D19: 3102.76 | E19: 1155.53 | F19: 552.5 | G19: 287.54 | H19: 212.46 | I19: 60 | J19: 35 | K19: 1752.5 | L19: 1265.78 | M19: 353.28 | N19: -303.55 | O19: =SUM(C19:N19) -> 8473.8
B20: NSF Fees | C20: 160 | D20: 80 | E20: 40 | F20: 0 | G20: 40 | H20: 120 | I20: 40 | J20: 80 | K20: 160 | L20: 120 | M20: 160 | N20: 80 | O20: =SUM(C20:N20) -> 1080
B21: One-Time Pet Fees | C21: 0 | D21: 0 | E21: 0 | F21: 0 | G21: 0 | H21: 450 | I21: 450 | J21: 451.81 | K21: 0 | L21: 450 | M21: 0 | N21: 450 | O21: =SUM(C21:N21) -> 2251.81
B22: Resident Damage Assessments- Quarterly | C22: 0 | D22: 0 | E22: 0 | F22: 0 | G22: 0 | H22: 0 | I22: 0 | J22: 0 | K22: 275 | L22: 908.23 | M22: 92.5 | N22: 0 | O22: =SUM(C22:N22) -> 1275.73
B23: Trash & Cleaning Fees | C23: 0 | D23: 0 | E23: -29.06 | F23: -88.61 | G23: -130.03 | H23: -65.75 | I23: 0 | J23: -57.64 | K23: 0 | L23: 0 | M23: 0 | N23: 0 | O23: =SUM(C23:N23) -> -371.09
B24: Resident Transfer Fees | C24: 250 | D24: 0 | E24: 0 | F24: 0 | G24: 0 | H24: 0 | I24: 0 | J24: 1700 | K24: 2010.92 | L24: -368.44 | M24: 1348.79 | N24: 253.85 | O24: =SUM(C24:N24) -> 5195.12
B25: Monthly Pet Rent | C25: 290.31 | D25: 259.69 | E25: 300 | F25: 250 | G25: 75 | H25: 125 | I25: 75 | J25: 150 | K25: 125 | L25: 100 | M25: 125 | N25: 150 | O25: =SUM(C25:N25) -> 2025
B26: Short Term Lease Premium | C26: 475 | D26: 475 | E26: 100 | F26: 100 | G26: 0 | H26: 0 | I26: 0 | J26: 0 | K26: 0 | L26: 0 | M26: 0 | N26: 0 | O26: =SUM(C26:N26) -> 1150
B27: Student Turnover - Interior Paint/Dry Wall Reimbursement | C27: 0 | D27: 173.62 | E27: 838.62 | F27: 50 | G27: 2169.34 | H27: -2342.61 | I27: 0 | J27: 0 | K27: 0 | L27: 0 | M27: 0 | N27: 0 | O27: =SUM(C27:N27) -> 888.97
B28: Student Turnover - Carpet Cleaning Reimbursement | C28: 0 | D28: 0 | E28: 0 | F28: 0 | G28: 0 | H28: 6.59 | I28: 0 | J28: 0 | K28: 0 | L28: 0 | M28: 0 | N28: 0 | O28: =SUM(C28:N28) -> 6.59
B29: Student Turnover - General Cleaning | D29: 200 | E29: 1903.28 | F29: 150 | G29: 2109.13 | H29: 650 | I29: 0 | J29: 90.72 | K29: 0 | L29: 360.35 | M29: 0 | N29: 0 | O29: =SUM(C29:N29) -> 5463.48
B30: Student Turnover - Miscellaneous Reimbursement | C30: 0 | D30: 50 | E30: 100 | F30: 0 | G30: 200 | H30: 50 | I30: 0 | J30: 0 | K30: 0 | L30: 0 | M30: 0 | N30: 0 | O30: =SUM(C30:N30) -> 400
B31: Utility Reimbursements - Residents | C31: 17208.71 | D31: 13273.54 | E31: 12732.35 | F31: 14287.09 | G31: 10701.66 | H31: 7769.16 | I31: 10129.73 | J31: 12436.12 | K31: 11106.65 | L31: 10735.03 | M31: 11493.22 | N31: 14259.07 | O31: =SUM(C31:N31) -> 146132.33
B32: Residential Other Revenues | C32: 20385.84 | D32: 19445.15 | E32: 18643.98 | F32: 16704.54 | G32: 16163.42 | H32: 8128.55 | I32: 11801.04 | J32: 16056.98 | K32: 16973.11 | L32: 14959.48 | M32: 15495.6 | N32: 16062.45 | O32: =SUM(C32:N32) -> 190820.14
B34: Income | C34: 146640.19 | D34: 161730.33 | E34: 127024.69 | F34: 116529.94 | G34: 121421.02 | H34: 126027.52 | I34: 121615.3 | J34: 125862.49 | K34: 125476.22 | L34: 115101.84 | M34: 120825.09 | N34: 126021.15 | O34: =SUM(C34:N34) -> 1534275.8
B36: Operating Expenses
B37: Mortgage | C37: 41985.09 | D37: 41985.09 | E37: 0 | F37: 41915 | G37: 41915.18 | H37: 41915 | I37: 41015 | J37: 41915.09 | K37: 41915.09 | L37: 41915.09 | M37: 41915.09 | N37: 41915.09 | O37: =SUM(C37:N37) -> 460305.81
B38: Payroll | C38: 11284.83 | D38: 14155.61 | E38: 13441.07 | F38: 12046.72 | G38: 15760.74 | H38: 9953.3 | I38: 9054.63 | J38: 10307.8 | K38: 11795.41 | L38: 13663.59 | M38: 7493.57 | N38: 9010.85 | O38: =SUM(C38:N38) -> 137968.12
B39: Payroll Taxes | C39: 2040.23 | D39: 3631.38 | E39: 3676.97 | F39: 3049.05 | G39: 5321.36 | H39: 2325.77 | I39: 2148.39 | J39: 2348.91 | K39: 1414.52 | L39: 3547.41 | M39: 1773.3 | N39: 2100.85 | O39: =SUM(C39:N39) -> 33378.14
B40: Payroll Processing Service | C40: 725.67 | D40: 965.72 | E40: 642.3 | F40: 952.02 | G40: 4269.02 | H40: 720.9 | I40: 826.09 | J40: 663.4 | K40: 2029.15 | L40: 884.16 | M40: 847.32 | N40: 723.95 | O40: =SUM(C40:N40) -> 14249.7
B41: Payroll & Related Costs | C41: 14050.73 | D41: 18752.71 | E41: 17760.34 | F41: 16047.79 | G41: 25351.12 | H41: 12999.97 | I41: 12029.11 | J41: 13320.11 | K41: 15239.08 | L41: 18095.16 | M41: 10114.19 | N41: 11835.65 | O41: =SUM(C41:N41) -> 185595.96
B43: Repairs & Maintenance
B44: Pool/Repairs | C44: 0 | D44: 0 | E44: 334.14 | F44: 549.29 | G44: 35.69 | H44: 0 | I44: 0 | J44: 0 | K44: 0 | L44: 0 | M44: 0 | N44: 0 | O44: =SUM(C44:N44) -> 919.12
B45: HVAC Supplies/Repairs | C45: 0 | D45: 0 | E45: 0 | F45: 378.31 | G45: 360.47 | H45: 0 | I45: 427.68 | J45: 0 | K45: 0 | L45: 0 | M45: 0 | N45: 0 | O45: =SUM(C45:N45) -> 1166.46
B46: Maintenance Supplies | C46: 4834.71 | D46: 3095.15 | E46: 19655.28 | F46: 26061.56 | G46: 15498.73 | H46: 7387.23 | I46: 4114.8 | J46: 7826.72 | K46: 4110.32 | L46: 4226.6 | M46: 5311.79 | N46: 3688.26 | O46: =SUM(C46:N46) -> 105811.15
B47: Repairs & Maintenance | C47: =C46 -> 4834.71 | D47: 3095.15 | E47: 19989.42 | F47: 26989.16 | G47: 15894.89 | H47: 7387.23 | I47: 4542.48 | J47: 7826.72 | K47: 4110.32 | L47: 4226.6 | M47: 5311.79 | N47: 3688.26 | O47: =SUM(C47:N47) -> 107896.73
B49: Turnover Expense
...

Sheet WTAMSH RR
A1: Bldg-Unit | B1: Unit Type | C1: SQFT | D1: Unit Status | E1: Resident | F1: Move-In | G1: Lease Start | H1: Lease End | I1: Expected Move-Out | J1: Market Rent | K1: Actual Charges | L1: Scheduled Charges | M1: Balance | N1: Deposit Held
A2: 1-112-A | B2: D1 | C2: 75.75 | D2: Occupied No Notice | E2: Model 1, Canyon | F2: 40798 | G2: 45139 | J2: 525 | K2: 13 | L2: 0 | M2: 20.13 | N2: 0
A3: 1-112-B | B3: D1 | C3: 75.75 | D3: Occupied No Notice | E3: Model 2, Canyon | F3: 40798 | G3: 45139 | J3: 525 | K3: 13 | L3: 0 | M3: 20.13 | N3: 0
A4: 1-112-C | B4: D1 | C4: 75.75 | D4: Occupied No Notice | E4: Model 3, Canyon | F4: 40798 | G4: 45139 | J4: 525 | K4: 13 | L4: 0 | M4: 20.13 | N4: 0
A5: 1-112-D | B5: D1 | C5: 75.75 | D5: Occupied No Notice | E5: Model 4, Canyon | F5: 40798 | G5: 45139 | J5: 525 | K5: 13 | L5: 0 | M5: 20.13 | N5: 0
A6: 1-113-A | B6: B1 | C6: 180 | D6: Notice Unrented | E6: Robles, Kimberlee | F6: 45499 | G6: 45860 | H6: 46227 | I6: 46227 | J6: 650 | K6: 821.13 | L6: 650 | M6: 0 | N6: 250
A7: 1-113-B | B7: B1 | C7: 180 | D7: Notice Unrented | E7: Robles, Mariah | F7: 45499 | G7: 45860 | H7: 46227 | I7: 46227 | J7: 1300 | K7: 781.19 | L7: 675 | M7: -0.84 | N7: 250
A8: 1-114-A | B8: D1 | C8: 281.25 | D8: Notice Rented | E8: Smith, Sydni | F8: 45863 | G8: 45863 | H8: 46227 | I8: 46227 | J8: 525 | K8: 591.36 | L8: 525 | M8: 13 | N8: 250
A9: 1-114-B | B9: D1 | C9: 281.25 | D9: Vacant Unrented Ready | E9: -- Vacant -- | J9: 1950 | K9: 0 | L9: 0 | N9: 0
A10: 1-114-C | B10: D1 | C10: 281.25 | D10: Notice Unrented | E10: Castro, Jalynn | F10: 45860 | G10: 45860 | H10: 46227 | I10: 46227 | J10: 1050 | K10: 566.36 | L10: 500 | M10: 20.13 | N10: 250
A11: 1-114-D | B11: D1 | C11: 281.25 | D11: Vacant Rented Ready | E11: -- Vacant -- | J11: 1900 | K11: 0 | L11: 0
A12: 1-115-A | B12: B1 | C12: 180 | D12: Notice Unrented | E12: Bonilla, Amy | F12: 45870 | G12: 45870 | H12: 46227 | I12: 46204 | J12: 650 | K12: 702.66 | L12: 650 | M12: 0 | N12: 250
A13: 1-115-B | B13: B1 | C13: 180 | D13: Occupied No Notice | E13: Warren, Kayla | F13: 45873 | G13: 45873 | H13: 46227 | J13: 650 | K13: 702.66 | L13: 650 | M13: 0 | N13: 250
A14: 1-116-A | B14: D1 | C14: 75.75 | D14: Vacant Rented Ready | E14: -- Vacant -- | J14: 1950 | K14: 0 | L14: 0
A15: 1-116-B | B15: D1 | C15: 75.75 | D15: Vacant Rented Ready | E15: -- Vacant -- | J15: 600 | K15: 0 | L15: 0
A16: 1-116-C | B16: D1 | C16: 75.75 | D16: Occupied No Notice | E16: Reynolds, Hunter | F16: 46174 | G16: 46174 | H16: 46599 | J16: 1200 | K16: 600 | L16: 525 | M16: 0 | N16: 0
A17: 1-116-D | B17: D1 | C17: 75.75 | D17: Vacant Rented Ready | E17: -- Vacant -- | J17: 600 | K17: 0 | L17: 0
A18: 1-117-A | B18: B1 | C18: 180 | D18: Occupied No Notice | E18: Kell, Jordon | F18: 45901 | G18: 45901 | H18: 46227 | J18: 650 | K18: 674.48 | L18: 650 | M18: 0 | N18: 250
A19: 1-117-B | B19: B1 | C19: 180 | D19: Occupied No Notice | E19: Rasmussen, Joshua | F19: 46037 | G19: 46037 | H19: 46227 | J19: 1450 | K19: 664.48 | L19: 640 | M19: 0 | N19: 250
A20: 1-118-A | B20: B1 | C20: 180 | D20: Occupied No Notice | E20: Contreraz, Jacob Jr | F20: 44774 | G20: 45860 | H20: 46227 | J20: 650 | K20: 721.33 | L20: 650 | M20: 0 | N20: 250
A21: 1-118-B | B21: B1 | C21: 180 | D21: Notice Unrented | E21: Dioquino, Jaron | F21: 45505 | G21: 45860 | H21: 46227 | I21: 46227 | J21: 650 | K21: 708.33 | L21: 650 | M21: 0 | N21: 250
A22: 1-121.5-A | B22: F1 | C22: 300 | D22: Vacant Unrented Ready | E22: -- Vacant -- | J22: 674 | K22: 0 | L22: 0 | N22: 0
A23: 1-121.5-B | B23: F1 | C23: 300 | D23: Occupied No Notice | E23: Whitman, James | F23: 45520 | G23: 45860 | H23: 46227 | J23: 599 | K23: 698.93 | L23: 599 | M23: -3581.96 | N23: 250
A24: 1-121-A | B24: OG | C24: 151.5 | D24: Occupied No Notice | E24: Murray, Adam | F24: 46174 | G24: 46174 | H24: 46592 | J24: 624 | K24: 592.5 | L24: 555 | M24: 0 | N24: 0
A25: 1-121-B | B25: OG | C25: 151.5 | D25: Occupied No Notice | E25: Murray, Adam | F25: 46174 | G25: 46174 | H25: 46592 | J25: 1248 | K25: 592.5 | L25: 555 | M25: 0 | N25: 0
A26: 1-122.5-A | B26: F1 | C26: 300 | D26: Occupied No Notice | E26: Long, Ryker | F26: 45505 | G26: 45860 | H26: 46227 | J26: 599 | K26: 640.74 | L26: 599 | M26: 0 | N26: 125
A27: 1-122.5-B | B27: F1 | C27: 300 | D27: Occupied No Notice | E27: Long, Ryker | F27: 45505 | G27: 45860 | H27: 46227 | J27: 599 | K27: 640.74 | L27: 599 | M27: 0 | N27: 125
A28: 1-122-A | B28: OG | C28: 262.5 | D28: Notice Unrented | E28: Cantu, Patricia | F28: 45520 | G28: 45860 | H28: 46227 | I28: 46227 | J28: 555 | K28: 645.59 | L28: 549 | M28: 371.35 | N28: 250
A29: 1-122-B | B29: OG | C29: 262.5 | D29: Vacant Unrented Not Ready | E29: -- Vacant -- | J29: 1248 | K29: 0 | L29: 0 | N29: 0
A30: 1-123-A | B30: B1 | C30: 180 | D30: Occupied No Notice | E30: Podmolik, Peyton | F30: 45890 | G30: 45890 | H30: 46227 | J30: 650 | K30: 719.73 | L30: 650 | M30: -23.12 | N30: 250
A31: 1-123-B | B31: B1 | C31: 180 | D31: Occupied No Notice | E31: Hodgson, Violet | F31: 45890 | G31: 45890 | H31: 46227 | J31: 650 | K31: 719.73 | L31: 650 | M31: 0 | N31: 250
A32: 1-124-A | B32: B1 | C32: 180 | D32: Occupied No Notice | E32: Hunt, Brennen | F32: 45474 | G32: 45860 | H32: 46227 | J32: 650 | K32: 695.49 | L32: 650 | M32: 0 | N32: 250
A33: 1-124-B | B33: B1 | C33: 180 | D33: Occupied No Notice | E33: Host, Kayden | F33: 45633 | G33: 45860 | H33: 46227 | J33: 650 | K33: 720.49 | L33: 675 | M33: 0 | N33: 250
A34: 1-125-A | B34: B1 | C34: 180 | D34: Occupied No Notice | E34: Baez, Angelika | F34: 45870 | G34: 45870 | H34: 46227 | J34: 650 | K34: 700.67 | L34: 650 | M34: 0 | N34: 250
A35: 1-125-B | B35: B1 | C35: 180 | D35: Occupied No Notice | E35: Mills, Jordyn | F35: 45870 | G35: 45890 | H35: 46227 | J35: 650 | K35: 700.67 | L35: 650 | M35: 0 | N35: 250
A36: 1-126-A | B36: B1 | C36: 180 | D36: Occupied No Notice | E36: Ruvalcaba, Marcela | F36: 46121 | G36: 46121 | H36: 46234 | J36: 650 | K36: 672.43 | L36: 650 | M36: 0 | N36: 250
A37: 1-126-B | B37: B1 | C37: 180 | D37: Occupied No Notice | E37: Silva-Gomez, Yasmeen | F37: 46146 | G37: 46146 | H37: 46234 | J37: 1450 | K37: 693 | L37: 693 | M37: 0 | N37: 0
A38: 1-127-A | B38: D1 | C38: 75.75 | D38: Vacant Unrented Ready | E38: -- Vacant -- | J38: 1200 | K38: 0 | L38: 0 | N38: 0
A39: 1-127-B | B39: D1 | C39: 75.75 | D39: Occupied No Notice | E39: Joseph, Jamaal | F39: 45505 | G39: 45860 | H39: 46227 | J39: 525 | K39: 608.09 | L39: 525 | M39: 0 | N39: 250
A40: 1-127-C | B40: D1 | C40: 75.75 | D40: Vacant Unrented Not Ready | E40: -- Vacant -- | J40: 600 | K40: 0 | L40: 0 | N40: 0
...

Sheet Amarillo UW
A1: Amarillo Multifamily
A2: 112 units | Built 1975 | T-12: Apr 2025–Mar 2026 | Independent / Conservative Case
A4: KEY ASSUMPTIONS | D4: FINANCING & EXIT
A5: # Units | B5: 112 | D5: Loan-to-Price (LTV) | E5: 0.7
A6: Year Built | B6: 1975 | D6: Loan Amount | E6: =B8*E5 -> 3920000
A7: Total SF | B7: ='Amarillo RR'!E121 -> 83440 | D7: Interest Rate | E7: 0.07
A8: Purchase Price | B8: 5600000 | D8: Amortization (yrs) | E8: 30
A9: Price / Unit | B9: =B8/B5 -> 50000 | D9: Closing Costs (% price) | E9: 0.02
A10: Hold Period (yrs) | B10: 4 | D10: Going-in Cap (normalized) | E10: =B38/B8 -> 0.074137833
D11: Exit Cap Rate | E11: 0.0825
A12: Rent Growth (annual) | B12: 0.03 | D12: Selling Costs (% sale) | E12: 0.02
A13: Other Income Growth | B13: 0.03 | D13: Total Equity Required | E13: =B8+B19+B8*E9-E6 -> 3461000
A14: Expense Inflation | B14: 0.03
A15: Stabilized Econ. Vacancy | B15: 0.07
A16: Mgmt Fee (% EGI) | B16: 0.035
A17: Replacement Reserves ($/unit) | B17: 250
A18: Reno Premium ($/unit/mo) | B18: 100
A19: Renovation Budget ($) | B19: 1669000
A21: IN-PLACE OPERATING STATEMENT (T-12, Normalized) | B21: T-12 Actual
A22: Rental Income (net of concessions/vouchers) | B22: ='Amarillo T12'!N19 -> 982442.15
A23: Other Income (fees, utility, deposit/maint, misc) | B23: ='Amarillo T12'!N51-'Amarillo T12'!N19 -> 101005.74
A24: Effective Gross Income | B24: =B22+B23 -> 1083447.9
A25: Repairs & Maintenance | B25: ='Amarillo T12'!N71 -> 161237.61
A26: Contracted Services | B26: ='Amarillo T12'!N76 -> 35887.65
A27: Cleaning & Janitorial | B27: ='Amarillo T12'!N80 -> 30112.6
A28: Utilities | B28: ='Amarillo T12'!N86 -> 107499.58
A29: Property Taxes | B29: ='Amarillo T12'!N89 -> 61639.03
A30: Insurance | B30: ='Amarillo T12'!N92 -> 91105.88
A31: Onsite Salaries & Wages | B31: ='Amarillo T12'!N97 -> 99022.64
A32: General & Administrative (incl. existing mgmt fee) | B32: ='Amarillo T12'!N59 -> 39165.1
A33: Misc. Operating | B33: ='Amarillo T12'!N103 -> 6204.02
A34: Total Operating Expenses (reported) | B34: =SUM(B25:B33) -> 631874.11
A35: NOI (as reported) | B35: =B24-B34 -> 451573.78
A36: (–) Normalize mgmt fee up to 3.5% of EGI | B36: =-MAX(0,B16*B24-'Amarillo T12'!N57) -> -8401.9162
A37: (–) Add replacement reserves ($/unit) | B37: =-B5*B17 -> -28000
A38: Normalized In-Place NOI | B38: =B35+B36+B37 -> 415171.86
A39: Normalized Going-in Cap Rate | B39: =B38/B8 -> 0.074137833
A42: PRO FORMA CASH FLOW
B43: In-Place | C43: Year 1 | D43: Year 2 | E43: Year 3 | F43: Year 4
A44: Rental & Other Income (grown) | B44: =B24 -> 1083447.9 | C44: =B44*(1+$B$12) -> 1115951.3 | D44: =C44*(1+$B$12) -> 1149429.9 | E44: =D44*(1+$B$12) -> 1183912.8 | F44: =E44*(1+$B$12) -> 1219430.1
...

Sheet Oak Cliff UW
A1: Oak Cliff Multifamily
A2: 136 units | Built 1974 | South Dallas | T-12 rolling 12mo | Independent / Conservative Case
A4: KEY ASSUMPTIONS | D4: FINANCING & EXIT
A5: # Units | B5: 136 | D5: Loan-to-Price (LTV) | E5: 0.7
A6: Year Built | B6: 1974 | D6: Loan Amount | E6: =B8*E5 -> 5075000
A7: Total SF | B7: ='Oak RR'!F140 -> 100302 | D7: Interest Rate | E7: 0.075
A8: Purchase Price | B8: 7250000 | D8: Amortization (yrs) | E8: 30
A9: Price / Unit | B9: =B8/B5 -> 53308.824 | D9: Closing Costs (% price) | E9: 0.02
A10: Hold Period (yrs) | B10: 5 | D10: Going-in Cap (normalized) | E10: =B33/B8 -> 0.096746066
D11: Exit Cap Rate | E11: 0.0925
A12: Rent Growth (annual) | B12: 0.03 | D12: Selling Costs (% sale) | E12: 0.02
A13: Other Income Growth | B13: 0.03 | D13: Total Equity Required | E13: =B8+B19+B8*E9-E6 -> 4156000
A14: Expense Inflation | B14: 0.03
A15: Stabilized Econ. Vacancy | B15: 0.07
A16: Mgmt Fee (% EGI) | B16: 0.035
A17: Replacement Reserves ($/unit) | B17: 250
A18: Rent Premium (reno + MTM, $/unit/mo) | B18: 110
A19: Renovation Budget ($) | B19: 1836000
A21: IN-PLACE OPERATING STATEMENT (T-12, Normalized) | B21: T-12 Actual
A22: Rental Income (net of concessions) | B22: ='Oak T-12'!N8+'Oak T-12'!N9 -> 1549904.8
A23: Other Income (fees, parking, misc) | B23: ='Oak T-12'!N23-('Oak T-12'!N8+'Oak T-12'!N9) -> 16842.91
A24: Effective Gross Income | B24: =B22+B23 -> 1566747.7
A25: Controllable Operating Expenses | B25: ='Oak T-12'!N44 -> 524060.05
A26: Management Fee | B26: ='Oak T-12'!N48 -> 62649.79
A27: Property Insurance | B27: ='Oak T-12'!N49 -> 73102.51
A28: Property Taxes | B28: ='Oak T-12'!N50 -> 179340
A29: Total Operating Expenses (reported) | B29: =SUM(B25:B28) -> 839152.35
A30: NOI (as reported) | B30: =B24-B29 -> 727595.36
A31: (±) Normalize mgmt fee to 3.5% of EGI | B31: ='Oak T-12'!N48-B16*B24 -> 7813.6201
A32: (–) Add replacement reserves ($/unit) | B32: =-B5*B17 -> -34000
A33: Normalized In-Place NOI | B33: =B30+B31+B32 -> 701408.98
A34: Normalized Going-in Cap Rate | B34: =B33/B8 -> 0.096746066
A42: PRO FORMA CASH FLOW
B43: In-Place | C43: Year 1 | D43: Year 2 | E43: Year 3 | F43: Year 4 | G43: Year 5
A44: Rental & Other Income (grown) | B44: =B24 -> 1566747.7 | C44: =B44*(1+$B$12) -> 1613750.1 | D44: =C44*(1+$B$12) -> 1662162.6 | E44: =D44*(1+$B$12) -> 1712027.5 | F44: =E44*(1+$B$12) -> 1763388.4 | G44: =F44*(1+$B$12) -> 1816290
A45: Rent premium % achieved | B45: 0 | C45: 0.4 | D45: 0.7 | E45: 1 | F45: 1 | G45: 1
A46: (+) Rent Premium ($) | B46: =$B$5*$B$18*12*B45 -> 0 | C46: =$B$5*$B$18*12*C45 -> 71808 | D46: =$B$5*$B$18*12*D45 -> 125664 | E46: =$B$5*$B$18*12*E45 -> 179520 | F46: =$B$5*$B$18*12*F45 -> 179520 | G46: =$B$5*$B$18*12*G45 -> 179520
A47: Effective Gross Income | B47: =B44+B46 -> 1566747.7 | C47: =C44+C46 -> 1685558.1 | D47: =D44+D46 -> 1787826.6 | E47: =E44+E46 -> 1891547.5 | F47: =F44+F46 -> 1942908.4 | G47: =G44+G46 -> 1995810
A49: Operating Expenses:
A50: Opex excl. mgmt fee & reserves (inflated) | B50: =B29-'Oak T-12'!N48 -> 776502.56 | C50: =B50*(1+$B$14) -> 799797.64 | D50: =C50*(1+$B$14) -> 823791.57 | E50: =D50*(1+$B$14) -> 848505.31 | F50: =E50*(1+$B$14) -> 873960.47 | G50: =F50*(1+$B$14) -> 900179.29
...

Sheet WTAMSH UW
A1: West Texas A&M Student Housing
A2: 336 beds / 114 units | Built 2006 | Canyon, TX | Lease-up play (55% → stabilized) | Independent / Conservative Case
A4: KEY ASSUMPTIONS | D4: FINANCING & EXIT
A5: # Beds | B5: 336 | D5: Loan-to-Price (LTV) | E5: 0.65
A6: # Units | B6: 114 | D6: Loan Amount | E6: =B8*E5 -> 7637500
A7: Year Built | B7: 2006 | D7: Interest Rate | E7: 0.07
A8: Purchase Price | B8: 11750000 | D8: Amortization (yrs) | E8: 30
A9: Price / Bed | B9: =B8/B5 -> 34970.238 | D9: Closing Costs (% price) | E9: 0.02
A10: Hold Period (yrs) | B10: 4 | D10: Going-in Cap (in-place, seller tax) | E10: =B36/B8 -> 0.060234551
D11: Exit Cap Rate | E11: 0.0825
A12: Effective Rent / Bed / Mo | B12: 540 | D12: Selling Costs (% sale) | E12: 0.02
A13: Rent Growth (annual) | B13: 0.03 | D13: Total Equity Required | E13: =B8+B19+B8*E9-E6 -> 4597500
A14: Expense Inflation | B14: 0.03
A15: Other Income Growth | B15: 0.03
A16: Mgmt Fee (% EGI) | B16: 0.04
A17: Replacement Reserves ($/bed) | B17: 150
A18: Property Tax Rate (% of price) | B18: 0.02
A19: Lease-up / Working Capital Reserve | B19: 250000
A21: IN-PLACE OPERATING STATEMENT (T-12, Normalized) | B21: T-12 (~55% occ)
A22: Rental Income (scheduled, ~55% occ) | B22: ='WTAMSH T-12'!O7 -> 1329425
A23: Other Income (fees, utility reimb.) | B23: ='WTAMSH T-12'!O34-'WTAMSH T-12'!O7 -> 204850.79
A24: Effective Gross Income | B24: =B22+B23 -> 1534275.8
A25: Payroll & Related | B25: ='WTAMSH T-12'!O41 -> 185595.96
A26: Repairs & Maintenance | B26: ='WTAMSH T-12'!O47 -> 107896.73
A27: Utilities (common + unit + turnover) | B27: ='WTAMSH T-12'!O58+'WTAMSH T-12'!O63+'WTAMSH T-12'!O51 -> 196648.14
A28: Marketing | B28: ='WTAMSH T-12'!O73 -> 11768.05
A29: Insurance | B29: ='WTAMSH T-12'!O105 -> 54009.71
A30: G&A & Other | B30: ='WTAMSH T-12'!O92+'WTAMSH T-12'!O101+'WTAMSH T-12'!O77 -> 19201.19
A31: Property Taxes (seller basis) | B31: ='WTAMSH T-12'!O138 -> 139629
A32: Total True Operating Expenses | B32: =SUM(B25:B31) -> 714748.78
A33: NOI before mgmt fee & reserves | B33: =B24-B32 -> 819527
A34: (–) Management Fee (% EGI) | B34: =-B24*B16 -> -61371.031
A35: (–) Replacement Reserves ($/bed) | B35: =-B5*B17 -> -50400
A36: Normalized In-Place NOI | B36: =B33+B34+B35 -> 707755.97
A37: Going-in Cap (in-place, seller tax) | B37: =B36/B8 -> 0.060234551
A38: Note: T-12 buried mortgage ($460K), owner distributions ($133K) & capex ($12K) in opex — excluded here to isolate true property NOI. In-place NOI is depressed by 55% occupancy.
A42: PRO FORMA CASH FLOW (Lease-Up)
B43: In-Place | C43: Year 1 | D43: Year 2 | E43: Year 3 | F43: Year 4
A44: Gross Potential Rent (100% occ) | B44: =B22/B45 -> 2417136.3 | C44: =$B$5*$B$12*12 -> 2177280 | D44: =C44*(1+$B$13) -> 2242598.4 | E44: =D44*(1+$B$13) -> 2309876.4 | F44: =E44*(1+$B$13) -> 2379172.6
A45: Economic Occupancy % | B45: 0.55 | C45: 0.75 | D45: 0.82 | E45: 0.86 | F45: 0.88
...

Sheet Deal Summary
A1: BLUE LION EQUITY PARTNERS — Independent Underwriting Summary
A2: Three multifamily deals | Independent / conservative case vs. sponsor projections | All figures deal-level (pre-promote)
B3: AMARILLO | D3: OAK CLIFF | F3: WTAMSH
A4: Metric | B4: Independent | C4: Sponsor | D4: Independent | E4: Sponsor | F4: Independent | G4: Sponsor
A5: Units / Beds | B5: ='Amarillo UW'!B5&" units" -> 112 units | D5: ='Oak Cliff UW'!B5&" units" -> 136 units | F5: ='WTAMSH UW'!B5&" beds" -> 336 beds
A6: Year Built | B6: ='Amarillo UW'!B6 -> 1975 | D6: ='Oak Cliff UW'!B6 -> 1974 | F6: ='WTAMSH UW'!B7 -> 2006
A7: Purchase Price | B7: ='Amarillo UW'!B8 -> 5600000 | D7: ='Oak Cliff UW'!B8 -> 7250000 | F7: ='WTAMSH UW'!B8 -> 11750000
A8: Price / Unit (Bed for WTAMSH) | B8: ='Amarillo UW'!B9 -> 50000 | D8: ='Oak Cliff UW'!B9 -> 53308.824 | F8: ='WTAMSH UW'!B9 -> 34970.238
A9: Normalized In-Place NOI | B9: ='Amarillo UW'!B38 -> 415171.86 | D9: ='Oak Cliff UW'!B33 -> 701408.98 | F9: ='WTAMSH UW'!B36 -> 707755.97
A10: Going-in Cap (normalized) | B10: ='Amarillo UW'!B39 -> 0.074137833 | C10: 0.0741 | D10: ='Oak Cliff UW'!B34 -> 0.096746066 | E10: 0.1004 | F10: ='WTAMSH UW'!B37 -> 0.060234551 | G10: 0.0711
A11: Hold Period (yrs) | B11: ='Amarillo UW'!B10 -> 4 | D11: ='Oak Cliff UW'!B10 -> 5 | F11: ='WTAMSH UW'!B10 -> 4
A12: Exit Cap Rate | B12: ='Amarillo UW'!E11 -> 0.0825 | C12: 0.08 | D12: ='Oak Cliff UW'!E11 -> 0.0925 | E12: 0.085 | F12: ='WTAMSH UW'!E11 -> 0.0825 | G12: 0.08
A13: Exit / Sale Value | B13: ='Amarillo UW'!F70 -> 7497024.6 | C13: 11562000 | D13: ='Oak Cliff UW'!G70 -> 11043575 | E13: 15847199 | F13: ='WTAMSH UW'!F70 -> 11708653 | G13: 19827732
A14: Equity Required (deal / sponsor LP) | B14: ='Amarillo UW'!E13 -> 3461000 | C14: 3980000 | D14: ='Oak Cliff UW'!E13 -> 4156000 | E14: 2910000 | F14: ='WTAMSH UW'!E13 -> 4597500 | G14: 4375000
A15: RETURNS
A16: Levered IRR | B16: ='Amarillo UW'!C78 -> 0.077154978 | C16: ='Amarillo UW'!E78 -> 0.2239 | D16: ='Oak Cliff UW'!C78 -> 0.17584602 | E16: ='Oak Cliff UW'!E78 -> 0.4276 | F16: ='WTAMSH UW'!C78 -> 0.026038357 | G16: ='WTAMSH UW'!E78 -> 0.3104
A17: Equity Multiple | B17: ='Amarillo UW'!C79 -> 1.3176701 | C17: ='Amarillo UW'!E79 -> 2.03 | D17: ='Oak Cliff UW'!C79 -> 2.0322532 | E17: ='Oak Cliff UW'!E79 -> 3 | F17: ='WTAMSH UW'!C79 -> 1.1029847 | G17: ='WTAMSH UW'!E79 -> 2.63
A18: Avg. Cash-on-Cash | B18: ='Amarillo UW'!C80 -> 0.06855823 | C18: ='Amarillo UW'!E80 -> 0.112 | D18: ='Oak Cliff UW'!C80 -> 0.11613359 | E18: ='Oak Cliff UW'!E80 -> 0.1186 | F18: ='WTAMSH UW'!C80 -> 0.047580543 | G18: ='WTAMSH UW'!E80 -> 0.126
A19: Unlevered IRR | B19: ='Amarillo UW'!C81 -> 0.073432383 | D19: ='Oak Cliff UW'!C81 -> 0.12445983 | F19: ='WTAMSH UW'!C81 -> 0.053422262
A21: BOTTOM LINE
A22: Risk-adjusted ranking (independent case): 1) OAK CLIFF — best in-place cap (~9.7%) and ~$297K/yr loss-to-lease; clears ~17.6% IRR / 2.03x even WITHOUT the sponsor's Year-2 refi. 2) AMARILLO — entry basis checks out (7.4% cap ties to sponsor), but ~7.7% base case needs the full value-add to reach target returns. 3) WTAMSH — richly priced ($103K/unit) for a 55%-occupied asset; ~2.6% base case, only works if aggressive lease-up AND rents are achieved.
A24: Where the sponsor and I diverge: (a) exit caps — I underwrite 50-100 bps wider; (b) NOI ramp — my conservative cases sit well below theirs; (c) Oak Cliff Year-2 refinance returning 100% of capital — I do not credit it; (d) WTAMSH property-tax reassessment to purchase price — I add it, they appear not to.
A26: Assumptions I set (all blue inputs on each tab are yours to flex): 3% rent growth & expense inflation; stabilized economic vacancy 7% (WTAMSH lease-up to 88%); management fee 3.5-4% of EGI and replacement reserves ADDED (the T-12s omit both); sponsor financing terms as base except WTAMSH (bridge: 65% LTV @ 7.0%).
A28: All returns are DEAL-LEVEL (before the GP promote, 8% preferred return, and 70/30 split). LP net-of-waterfall returns would be lower. Green = linked from property tabs; grey = sponsor's stated figures from the decks.
A30: What the underwriting surfaced
A31: Amarillo - my normalized in-place NOI (~$415K) lands exactly on the sponsor's stated 7.41% going-in cap, so their entry basis checks out. But their Year-4 sale (>2x purchase, ~$925K exit NOI vs my ~$600K) needs a very aggressive ramp.
A32: Oak Cliff - the strongest deal. Genuine ~$182/unit/mo loss-to-lease and a ~9.7% in-place cap; it clears ~17.6% even without the sponsor's Year-2 refi. The gap to their 42.8% is almost entirely that refi plus an 8.5% exit vs my 9.25%.
A33: WTAMSH - the riskiest. You're paying $35K/bed for a 55%-occupied asset (a 6.0% in-place cap), so returns hinge entirely on lease-up. Its T-12 also buried mortgage ($460K), owner draws ($133K) and capex in operating expenses - I stripped those out to isolate true NOI. On conservative assumptions it barely returns capital.
A34: My conservative levers (all blue inputs you can flex): 3% rent growth & expense inflation, stabilized vacancy 7% (student 12%), a market mgmt fee + replacement reserves added (both T-12s omit them), exit caps above the sponsor's, and a property-tax reassessment on WTAMSH.
A36: Two caveats worth knowing: returns are deal-level (LP net-of-waterfall would be lower after the 8% pref / 70-30 split), and Amarillo had only a one-pager, so its revenue is anchored to the T-12 rather than a full rent-roll build. Adjust any blue input and everything reflows.
